Workbook

Sheet Page 1
E2: Vérification de l'homogeniété et de la stabilité des échantillons soumises à l'essai d'aptitude | S2: Réference : FTE 006 Version : 06 du 10/08/2026 Page 1/6
D9: Version | G9: Date | J9: Résumé des modifications
D11: 1 | J11: Création
D14: 2
D17: 3
D20: 4
D23: 5 | G23: 46075 | J23: ajout de feuille pour la séléction automatique des entitées
D24: 6 | G24: 46244 | J24: Élargissement du facteur appliqué au critère de vérification de l’homogénéité (B.2.3) pour m ≥ 2
D25: 7
F27: Rédacteur | I27: Approbateur
D29: Fonction | F29: Responsable essais d'aptitude | I29: Responsable Technique et Scientifique
D32: Signature
B37: Adresse : BP53 Zone Industrielle Technopole Menzel Harb 5036 TUNISIE Tél : +216 70 146 260 Fax : +216 70 146 269 Mail : info@ttesting.org

Sheet Selection des entités
E2: Vérification de l'homogeniété et de la stabilité des échantillons soumises à l'essai d'aptitude | V2: Réference : FTE 006 Version : 06 du 10/08/2026 Page 2/6
B7: Sélection aléatoire intelligente d'échantillons (tirage sans remise)
B9: I) Paramètres
B10: N : nombre total de lots / échantillons produits | C10: 25 | E10: =IF(C10<C11,"Impossible : N ("&C10&") est inferieur a k ("&C11&"). Augmentez N ou reduisez le nombre de libelles.",IF(C10>200,"N depasse la capacite de cette feuille (200 lots max). Voir la note en bas de page.","OK : "&C10&" lots au total, "&C11&" a selectionner, "&(C10-C11)&" en reserve.")) -> OK : 25 lots au total, 12 a selectionner, 13 en reserve.
B11: k : nombre d'échantillons à sélectionner (= nb. de libellés renseignés ci-dessous) | C11: =COUNTA(B15:U15) -> 12
B12: Validation :
B14: II) Résultat du tirage — libellés modifiables, tirage automatique
A15: Libellé | B15: H-001 | C15: H-002 | D15: H-003 | E15: H-004 | F15: H-005 | G15: H-006 | H15: H-007 | I15: H-008 | J15: H-009 | K15: H-010 | L15: ST-001 | M15: STE-002
A16: N° de lot tiré | B16: =IF(B15="","",IFERROR(INDEX($B$65:$B$264,MATCH(1,$D$65:$D$264,0)),"")) -> 3 | C16: =IF(C15="","",IFERROR(INDEX($B$65:$B$264,MATCH(2,$D$65:$D$264,0)),"")) -> 4 | D16: =IF(D15="","",IFERROR(INDEX($B$65:$B$264,MATCH(3,$D$65:$D$264,0)),"")) -> 19 | E16: =IF(E15="","",IFERROR(INDEX($B$65:$B$264,MATCH(4,$D$65:$D$264,0)),"")) -> 2 | F16: =IF(F15="","",IFERROR(INDEX($B$65:$B$264,MATCH(5,$D$65:$D$264,0)),"")) -> 7 | G16: =IF(G15="","",IFERROR(INDEX($B$65:$B$264,MATCH(6,$D$65:$D$264,0)),"")) -> 16 | H16: =IF(H15="","",IFERROR(INDEX($B$65:$B$264,MATCH(7,$D$65:$D$264,0)),"")) -> 12 | I16: =IF(I15="","",IFERROR(INDEX($B$65:$B$264,MATCH(8,$D$65:$D$264,0)),"")) -> 18 | J16: =IF(J15="","",IFERROR(INDEX($B$65:$B$264,MATCH(9,$D$65:$D$264,0)),"")) -> 6 | K16: =IF(K15="","",IFERROR(INDEX($B$65:$B$264,MATCH(10,$D$65:$D$264,0)),"")) -> 5 | L16: =IF(L15="","",IFERROR(INDEX($B$65:$B$264,MATCH(11,$D$65:$D$264,0)),"")) -> 25 | M16: =IF(M15="","",IFERROR(INDEX($B$65:$B$264,MATCH(12,$D$65:$D$264,0)),"")) -> 24 | N16: =IF(N15="","",IFERROR(INDEX($B$65:$B$264,MATCH(13,$D$65:$D$264,0)),"")) | O16: =IF(O15="","",IFERROR(INDEX($B$65:$B$264,MATCH(14,$D$65:$D$264,0)),"")) | P16: =IF(P15="","",IFERROR(INDEX($B$65:$B$264,MATCH(15,$D$65:$D$264,0)),"")) | Q16: =IF(Q15="","",IFERROR(INDEX($B$65:$B$264,MATCH(16,$D$65:$D$264,0)),"")) | R16: =IF(R15="","",IFERROR(INDEX($B$65:$B$264,MATCH(17,$D$65:$D$264,0)),"")) | S16: =IF(S15="","",IFERROR(INDEX($B$65:$B$264,MATCH(18,$D$65:$D$264,0)),"")) | T16: =IF(T15="","",IFERROR(INDEX($B$65:$B$264,MATCH(19,$D$65:$D$264,0)),"")) | U16: =IF(U15="","",IFERROR(INDEX($B$65:$B$264,MATCH(20,$D$65:$D$264,0)),""))
B18: Renseignez les libellés en bleu (ligne 8) dans l'ordre voulu, sans laisser de case vide entre deux libellés (les cases doivent être remplies à partir de la gauche). Le n° de lot tiré apparaît automatiquement en ligne 9. Pour tirer un nouveau jeu aléatoire, appuyez sur F9 (recalcul).
B20: IMPORTANT — Le tirage utilise la fonction RAND() : il change à CHAQUE recalcul et à CHAQUE réouverture du fichier. Une fois le tirage retenu pour l'essai réel, figez-le immédiatement : sélectionnez les lignes 8-9 (et le tableau ci-dessous), Copier, puis Collage spécial > Valeurs, avant d'archiver ou d'imprimer le document. Sans cette étape, le tirage affiché ne sera pas reproductible et perdra toute valeur de preuve.
C28: Adresse : BP53 Zone Industrielle Technopole Menzel Harb 5036 TUNISIE Tél : +216 70 146 260 Fax : +216 70 146 269 Mail : info@ttesting.org
B63: III) Population complète, clé aléatoire, rang et statut (table d'audit — sert aussi de liste de réserve)
B64: N° de lot | C64: Clé aléatoire | D64: Rang du tirage | E64: Statut
B65: =IF(1<=$C$10,1,"") -> 1 | C65: =IF(B65="","",RAND()) -> 0.59684737 | D65: =IF(B65="","",RANK(C65,$C$65:$C$264,1)) -> 20 | E65: =IF(B65="","",IF(D65<=$C$11,"Selectionne - "&INDEX($B$15:$U$15,D65),"Reserve")) -> Reserve
B66: =IF(2<=$C$10,2,"") -> 2 | C66: =IF(B66="","",RAND()) -> 0.20642828 | D66: =IF(B66="","",RANK(C66,$C$65:$C$264,1)) -> 4 | E66: =IF(B66="","",IF(D66<=$C$11,"Selectionne - "&INDEX($B$15:$U$15,D66),"Reserve")) -> Selectionne - H-004
B67: =IF(3<=$C$10,3,"") -> 3 | C67: =IF(B67="","",RAND()) -> 0.033242758 | D67: =IF(B67="","",RANK(C67,$C$65:$C$264,1)) -> 1 | E67: =IF(B67="","",IF(D67<=$C$11,"Selectionne - "&INDEX($B$15:$U$15,D67),"Reserve")) -> Selectionne - H-001
B68: =IF(4<=$C$10,4,"") -> 4 | C68: =IF(B68="","",RAND()) -> 0.048695161 | D68: =IF(B68="","",RANK(C68,$C$65:$C$264,1)) -> 2 | E68: =IF(B68="","",IF(D68<=$C$11,"Selectionne - "&INDEX($B$15:$U$15,D68),"Reserve")) -> Selectionne - H-002
B69: =IF(5<=$C$10,5,"") -> 5 | C69: =IF(B69="","",RAND()) -> 0.38589146 | D69: =IF(B69="","",RANK(C69,$C$65:$C$264,1)) -> 10 | E69: =IF(B69="","",IF(D69<=$C$11,"Selectionne - "&INDEX($B$15:$U$15,D69),"Reserve")) -> Selectionne - H-010
B70: =IF(6<=$C$10,6,"") -> 6 | C70: =IF(B70="","",RAND()) -> 0.35720671 | D70: =IF(B70="","",RANK(C70,$C$65:$C$264,1)) -> 9 | E70: =IF(B70="","",IF(D70<=$C$11,"Selectionne - "&INDEX($B$15:$U$15,D70),"Reserve")) -> Selectionne - H-009
B71: =IF(7<=$C$10,7,"") -> 7 | C71: =IF(B71="","",RAND()) -> 0.21532281 | D71: =IF(B71="","",RANK(C71,$C$65:$C$264,1)) -> 5 | E71: =IF(B71="","",IF(D71<=$C$11,"Selectionne - "&INDEX($B$15:$U$15,D71),"Reserve")) -> Selectionne - H-005
B72: =IF(8<=$C$10,8,"") -> 8 | C72: =IF(B72="","",RAND()) -> 0.51304975 | D72: =IF(B72="","",RANK(C72,$C$65:$C$264,1)) -> 17 | E72: =IF(B72="","",IF(D72<=$C$11,"Selectionne - "&INDEX($B$15:$U$15,D72),"Reserve")) -> Reserve
B73: =IF(9<=$C$10,9,"") -> 9 | C73: =IF(B73="","",RAND()) -> 0.99666903 | D73: =IF(B73="","",RANK(C73,$C$65:$C$264,1)) -> 25 | E73: =IF(B73="","",IF(D73<=$C$11,"Selectionne - "&INDEX($B$15:$U$15,D73),"Reserve")) -> Reserve
B74: =IF(10<=$C$10,10,"") -> 10 | C74: =IF(B74="","",RAND()) -> 0.5295926 | D74: =IF(B74="","",RANK(C74,$C$65:$C$264,1)) -> 18 | E74: =IF(B74="","",IF(D74<=$C$11,"Selectionne - "&INDEX($B$15:$U$15,D74),"Reserve")) -> Reserve
B75: =IF(11<=$C$10,11,"") -> 11 | C75: =IF(B75="","",RAND()) -> 0.48610549 | D75: =IF(B75="","",RANK(C75,$C$65:$C$264,1)) -> 15 | E75: =IF(B75="","",IF(D75<=$C$11,"Selectionne - "&INDEX($B$15:$U$15,D75),"Reserve")) -> Reserve
B76: =IF(12<=$C$10,12,"") -> 12 | C76: =IF(B76="","",RAND()) -> 0.33012149 | D76: =IF(B76="","",RANK(C76,$C$65:$C$264,1)) -> 7 | E76: =IF(B76="","",IF(D76<=$C$11,"Selectionne - "&INDEX($B$15:$U$15,D76),"Reserve")) -> Selectionne - H-007
B77: =IF(13<=$C$10,13,"") -> 13 | C77: =IF(B77="","",RAND()) -> 0.71077368 | D77: =IF(B77="","",RANK(C77,$C$65:$C$264,1)) -> 22 | E77: =IF(B77="","",IF(D77<=$C$11,"Selectionne - "&INDEX($B$15:$U$15,D77),"Reserve")) -> Reserve
B78: =IF(14<=$C$10,14,"") -> 14 | C78: =IF(B78="","",RAND()) -> 0.58500878 | D78: =IF(B78="","",RANK(C78,$C$65:$C$264,1)) -> 19 | E78: =IF(B78="","",IF(D78<=$C$11,"Selectionne - "&INDEX($B$15:$U$15,D78),"Reserve")) -> Reserve
B79: =IF(15<=$C$10,15,"") -> 15 | C79: =IF(B79="","",RAND()) -> 0.46835979 | D79: =IF(B79="","",RANK(C79,$C$65:$C$264,1)) -> 14 | E79: =IF(B79="","",IF(D79<=$C$11,"Selectionne - "&INDEX($B$15:$U$15,D79),"Reserve")) -> Reserve
B80: =IF(16<=$C$10,16,"") -> 16 | C80: =IF(B80="","",RAND()) -> 0.24052013 | D80: =IF(B80="","",RANK(C80,$C$65:$C$264,1)) -> 6 | E80: =IF(B80="","",IF(D80<=$C$11,"Selectionne - "&INDEX($B$15:$U$15,D80),"Reserve")) -> Selectionne - H-006
B81: =IF(17<=$C$10,17,"") -> 17 | C81: =IF(B81="","",RAND()) -> 0.93986811 | D81: =IF(B81="","",RANK(C81,$C$65:$C$264,1)) -> 24 | E81: =IF(B81="","",IF(D81<=$C$11,"Selectionne - "&INDEX($B$15:$U$15,D81),"Reserve")) -> Reserve
B82: =IF(18<=$C$10,18,"") -> 18 | C82: =IF(B82="","",RAND()) -> 0.33828852 | D82: =IF(B82="","",RANK(C82,$C$65:$C$264,1)) -> 8 | E82: =IF(B82="","",IF(D82<=$C$11,"Selectionne - "&INDEX($B$15:$U$15,D82),"Reserve")) -> Selectionne - H-008
B83: =IF(19<=$C$10,19,"") -> 19 | C83: =IF(B83="","",RAND()) -> 0.15103428 | D83: =IF(B83="","",RANK(C83,$C$65:$C$264,1)) -> 3 | E83: =IF(B83="","",IF(D83<=$C$11,"Selectionne - "&INDEX($B$15:$U$15,D83),"Reserve")) -> Selectionne - H-003
B84: =IF(20<=$C$10,20,"") -> 20 | C84: =IF(B84="","",RAND()) -> 0.51108358 | D84: =IF(B84="","",RANK(C84,$C$65:$C$264,1)) -> 16 | E84: =IF(B84="","",IF(D84<=$C$11,"Selectionne - "&INDEX($B$15:$U$15,D84),"Reserve")) -> Reserve
B85: =IF(21<=$C$10,21,"") -> 21 | C85: =IF(B85="","",RAND()) -> 0.46139095 | D85: =IF(B85="","",RANK(C85,$C$65:$C$264,1)) -> 13 | E85: =IF(B85="","",IF(D85<=$C$11,"Selectionne - "&INDEX($B$15:$U$15,D85),"Reserve")) -> Reserve
B86: =IF(22<=$C$10,22,"") -> 22 | C86: =IF(B86="","",RAND()) -> 0.81627141 | D86: =IF(B86="","",RANK(C86,$C$65:$C$264,1)) -> 23 | E86: =IF(B86="","",IF(D86<=$C$11,"Selectionne - "&INDEX($B$15:$U$15,D86),"Reserve")) -> Reserve
B87: =IF(23<=$C$10,23,"") -> 23 | C87: =IF(B87="","",RAND()) -> 0.71075909 | D87: =IF(B87="","",RANK(C87,$C$65:$C$264,1)) -> 21 | E87: =IF(B87="","",IF(D87<=$C$11,"Selectionne - "&INDEX($B$15:$U$15,D87),"Reserve")) -> Reserve
B88: =IF(24<=$C$10,24,"") -> 24 | C88: =IF(B88="","",RAND()) -> 0.40697661 | D88: =IF(B88="","",RANK(C88,$C$65:$C$264,1)) -> 12 | E88: =IF(B88="","",IF(D88<=$C$11,"Selectionne - "&INDEX($B$15:$U$15,D88),"Reserve")) -> Selectionne - STE-002
B89: =IF(25<=$C$10,25,"") -> 25 | C89: =IF(B89="","",RAND()) -> 0.39950142 | D89: =IF(B89="","",RANK(C89,$C$65:$C$264,1)) -> 11 | E89: =IF(B89="","",IF(D89<=$C$11,"Selectionne - "&INDEX($B$15:$U$15,D89),"Reserve")) -> Selectionne - ST-001
B90: =IF(26<=$C$10,26,"") | C90: =IF(B90="","",RAND()) | D90: =IF(B90="","",RANK(C90,$C$65:$C$264,1)) | E90: =IF(B90="","",IF(D90<=$C$11,"Selectionne - "&INDEX($B$15:$U$15,D90),"Reserve"))
...

Sheet Homogénéité-stabilité-quantita 
AF1: Pas de tendance significative, passez à l'évaulation de l'homognéité
E2: Vérification de l'homogeniété et de la stabilité des échantillons soumises à l'essai d'aptitude | Y2: Réference : FTE 006 Version : 06 du 10/08/2026 Page 3/6 | AF2: Présence de tendance significative, voir annexe B paragraphe. B.2.1.a) de l'ISO 13528 page 49
AF3: Pas de tendance significative, passez à l'évaulation de l'homognéité
AF4: Présence de tendance significative, voir annexe B paragraphe. B.2.1.b) de l'ISO 13528 page 50
AF5: Le rapport sr/σpt est inférieur à 0,5
E6: ESSAIS QUANTITATIFS
AF8: Pas de valeurs aberrantes détectées
E9: Référence de la campagne : | AF9: Le rapport sr/σpt est supérieur ou égal à 0,5
E10: Référence de l'échantillon testé : | AF10: Les échantillons sont homogènes
E11: Méthode testée : | AF11: Les échantillons ne sont pas homogènes
E12: Choix du mode d'expression du σpt Indiquer σpt au niveau I.5) dans le tableau avant de commencer l'évaluation de l'homogénéité et la stabilité: | O12: relatif | AF12: L'échantillon n'est pas homogène, utiliser σ'pt pour évaluer la performance
AF13: L'échantillon n'est pas homogène et le critère n'est pas vérifié
B14: I) Vérification de l'homogénieté des échantillons selon l'ISO 13528 : 2022 Annexe B page 49-53 | AF14: Valeur correcte
AF15: Valeur isolée
B16: I.1) | C16: Date des essais d'homogéniété: | AF16: Valeur abérrante
C17: Nombre d'échantillons ( g ) | F17: =IF(D23="","",COUNT(D23:D42)) | AF17: Les échantillons sont stables
C18: Nombre de prise d'essai ( m ) | F18: =IF(D23="","",COUNT(D23:I23)) | AF18: Les échantillons ne sont pas stables
AF19: L'entité soumise à l'essai n'est pas sensible au transport et ses conditions
B20: Code des rapports TTS | C20: Echantillon par ordre de réalisation des essais | D20: Résultat 1 | E20: Résultat 2 | F20: Résultat 3 | G20: Résultat 4 | H20: Résultat 5 | I20: Résultat 6 | J20: Moyenne x̄t | K20: St² | T20: I.4-a) | AF20: L'entité soumise à l'essai est sensible au transport et ses conditions
T21: Analyse de tendance de la distribution des résultats 1, 2, 3, 4, 5, 6 | AF21: L'entité soumise à l'essai ne risque pas d'être instable jusqu'à la fin de l'essai d'aptitude
AF22: L'entité soumise à l'essai risque d'être instable jusqu'à la fin de l'essai d'aptitude
C23: HO 001 | J23: =IF(D23="","",(1/$F$18)*SUM(D23:I23)) | K23: =IF(D23="","",(1/($F$18-1))*DEVSQ(D23:I23)) | AF23: Les échantillons ne sont pas suffisamment homogènes
C24: HO 002 | J24: =IF(D24="","",(1/$F$18)*SUM(D24:I24)) | K24: =IF(D24="","",(1/($F$18-1))*DEVSQ(D24:I24)) | AF24: Les échantillons sont suffisament homogènes
C25: HO 003 | J25: =IF(D25="","",(1/$F$18)*SUM(D25:I25)) | K25: =IF(D25="","",(1/($F$18-1))*DEVSQ(D25:I25)) | T25: =IF(T22=AF2, "Indiquer le numéro de la fiche d'action", "")
C26: HO 004 | J26: =IF(D26="","",(1/$F$18)*SUM(D26:I26)) | K26: =IF(D26="","",(1/($F$18-1))*DEVSQ(D26:I26)) | AF26: absolu
C27: HO 005 | J27: =IF(D27="","",(1/$F$18)*SUM(D27:I27)) | K27: =IF(D27="","",(1/($F$18-1))*DEVSQ(D27:I27)) | AF27: relatif
C28: HO 006 | J28: =IF(D28="","",(1/$F$18)*SUM(D28:I28)) | K28: =IF(D28="","",(1/($F$18-1))*DEVSQ(D28:I28))
C29: HO 007 | J29: =IF(D29="","",(1/$F$18)*SUM(D29:I29)) | K29: =IF(D29="","",(1/($F$18-1))*DEVSQ(D29:I29))
C30: HO 008 | J30: =IF(D30="","",(1/$F$18)*SUM(D30:I30)) | K30: =IF(D30="","",(1/($F$18-1))*DEVSQ(D30:I30))
C31: HO 009 | J31: =IF(D31="","",(1/$F$18)*SUM(D31:I31)) | K31: =IF(D31="","",(1/($F$18-1))*DEVSQ(D31:I31))
C32: HO 010 | J32: =IF(D32="","",(1/$F$18)*SUM(D32:I32)) | K32: =IF(D32="","",(1/($F$18-1))*DEVSQ(D32:I32))
J33: =IF(D33="","",(1/$F$18)*SUM(D33:I33)) | K33: =IF(D33="","",(1/($F$18-1))*DEVSQ(D33:I33)) | T33: I.4-b)
J34: =IF(D34="","",(1/$F$18)*SUM(D34:I34)) | K34: =IF(D34="","",(1/($F$18-1))*DEVSQ(D34:I34)) | T34: Analyse de tendance de la distribution des moyennes
J35: =IF(D35="","",(1/$F$18)*SUM(D35:I35)) | K35: =IF(D35="","",(1/($F$18-1))*DEVSQ(D35:I35))
J36: =IF(D36="","",(1/$F$18)*SUM(D36:I36)) | K36: =IF(D36="","",(1/($F$18-1))*DEVSQ(D36:I36))
J37: =IF(D37="","",(1/$F$18)*SUM(D37:I37)) | K37: =IF(D37="","",(1/($F$18-1))*DEVSQ(D37:I37))
J38: =IF(D38="","",(1/$F$18)*SUM(D38:I38)) | K38: =IF(D38="","",(1/($F$18-1))*DEVSQ(D38:I38)) | T38: =IF(T35=AF4, "Indiquer le numéro de la fiche d'action", "")
J39: =IF(D39="","",(1/$F$18)*SUM(D39:I39)) | K39: =IF(D39="","",(1/($F$18-1))*DEVSQ(D39:I39))
J40: =IF(D40="","",(1/$F$18)*SUM(D40:I40)) | K40: =IF(D40="","",(1/($F$18-1))*DEVSQ(D40:I40))
J41: =IF(D41="","",(1/$F$18)*SUM(D41:I41)) | K41: =IF(D41="","",(1/($F$18-1))*DEVSQ(D41:I41))
...

Sheet Test de cochran
E2: Vérification de l'homogeniété et de la stabilité des échantillons soumises à l'essai d'aptitude | M2: Réference : FTE 006 Version : 06 du 10/08/2026 Page 4/6
C6: TEST DE COCHRAN - ESSAIS QUANTITATIFS
D9: Référence de la campagne : | G9: =IF(D19="","",'Homogénéité-stabilité-quantita '!O9)
D10: Référence de l'échantillon testé : | G10: =IF(D19="","",'Homogénéité-stabilité-quantita '!O10)
D11: Méthode testée : | G11: =IF(D19="","",'Homogénéité-stabilité-quantita '!O11)
C13: Nombre d'échantillons ( g ) | F13: =IF(D19="","",COUNT(D19:D38))
C14: Nombre de prise d'essai ( m ) | F14: =IF(D19="","",COUNT(D19:I19))
B16: Code des rapports TTS | C16: Echantillon par ordre de réalisation des essais | D16: Résultat 1 | E16: Résultat 2 | F16: Résultat 3 | G16: Résultat 4 | H16: Résultat 5 | I16: Résultat 6 | J16: Si² | M16: Valeurs critiques pour le test de Cochran ISO 5725-2 : 2019 (p33)
M18: p laboratoires | N18: n=2 | P18: n=3 | R18: n=4 | T18: n=5 | V18: n=6
B19: =IF('Homogénéité-stabilité-quantita '!D23="","",'Homogénéité-stabilité-quantita '!B23) | C19: =IF('Homogénéité-stabilité-quantita '!D23="","",'Homogénéité-stabilité-quantita '!C23) | D19: =IF('Homogénéité-stabilité-quantita '!D23="","",'Homogénéité-stabilité-quantita '!D23) | E19: =IF('Homogénéité-stabilité-quantita '!E23="","",'Homogénéité-stabilité-quantita '!E23) | F19: =IF('Homogénéité-stabilité-quantita '!F23="","",'Homogénéité-stabilité-quantita '!F23) | G19: =IF('Homogénéité-stabilité-quantita '!G23="","",'Homogénéité-stabilité-quantita '!G23) | H19: =IF('Homogénéité-stabilité-quantita '!H23="","",'Homogénéité-stabilité-quantita '!H23) | I19: =IF('Homogénéité-stabilité-quantita '!I23="","",'Homogénéité-stabilité-quantita '!I23) | J19: =IF(D19="","",(STDEV(D19:I19))^2) | K19: =C19 | N19: 0.01 | O19: 0.05 | P19: 0.01 | Q19: 0.05 | R19: 0.01 | S19: 0.05 | T19: 0.01 | U19: 0.05 | V19: 0.01 | W19: 0.05
B20: =IF('Homogénéité-stabilité-quantita '!D24="","",'Homogénéité-stabilité-quantita '!B24) | C20: =IF('Homogénéité-stabilité-quantita '!D24="","",'Homogénéité-stabilité-quantita '!C24) | D20: =IF('Homogénéité-stabilité-quantita '!D24="","",'Homogénéité-stabilité-quantita '!D24) | E20: =IF('Homogénéité-stabilité-quantita '!E24="","",'Homogénéité-stabilité-quantita '!E24) | F20: =IF('Homogénéité-stabilité-quantita '!F24="","",'Homogénéité-stabilité-quantita '!F24) | G20: =IF('Homogénéité-stabilité-quantita '!G24="","",'Homogénéité-stabilité-quantita '!G24) | H20: =IF('Homogénéité-stabilité-quantita '!H24="","",'Homogénéité-stabilité-quantita '!H24) | I20: =IF('Homogénéité-stabilité-quantita '!I24="","",'Homogénéité-stabilité-quantita '!I24) | J20: =IF(D20="","",(STDEV(D20:I20))^2) | K20: =C20 | M20: 2 | N20: - | O20: - | P20: 0.995 | Q20: 0.975 | R20: 0.979 | S20: 0.939 | T20: 0.959 | U20: 0.906 | V20: 0.937 | W20: 0.877
B21: =IF('Homogénéité-stabilité-quantita '!D25="","",'Homogénéité-stabilité-quantita '!B25) | C21: =IF('Homogénéité-stabilité-quantita '!D25="","",'Homogénéité-stabilité-quantita '!C25) | D21: =IF('Homogénéité-stabilité-quantita '!D25="","",'Homogénéité-stabilité-quantita '!D25) | E21: =IF('Homogénéité-stabilité-quantita '!E25="","",'Homogénéité-stabilité-quantita '!E25) | F21: =IF('Homogénéité-stabilité-quantita '!F25="","",'Homogénéité-stabilité-quantita '!F25) | G21: =IF('Homogénéité-stabilité-quantita '!G25="","",'Homogénéité-stabilité-quantita '!G25) | H21: =IF('Homogénéité-stabilité-quantita '!H25="","",'Homogénéité-stabilité-quantita '!H25) | I21: =IF('Homogénéité-stabilité-quantita '!I25="","",'Homogénéité-stabilité-quantita '!I25) | J21: =IF(D21="","",(STDEV(D21:I21))^2) | K21: =C21 | M21: 3 | N21: 0.993 | O21: 0.967 | P21: 0.942 | Q21: 0.871 | R21: 0.883 | S21: 0.798 | T21: 0.834 | U21: 0.746 | V21: 0.793 | W21: 0.707
B22: =IF('Homogénéité-stabilité-quantita '!D26="","",'Homogénéité-stabilité-quantita '!B26) | C22: =IF('Homogénéité-stabilité-quantita '!D26="","",'Homogénéité-stabilité-quantita '!C26) | D22: =IF('Homogénéité-stabilité-quantita '!D26="","",'Homogénéité-stabilité-quantita '!D26) | E22: =IF('Homogénéité-stabilité-quantita '!E26="","",'Homogénéité-stabilité-quantita '!E26) | F22: =IF('Homogénéité-stabilité-quantita '!F26="","",'Homogénéité-stabilité-quantita '!F26) | G22: =IF('Homogénéité-stabilité-quantita '!G26="","",'Homogénéité-stabilité-quantita '!G26) | H22: =IF('Homogénéité-stabilité-quantita '!H26="","",'Homogénéité-stabilité-quantita '!H26) | I22: =IF('Homogénéité-stabilité-quantita '!I26="","",'Homogénéité-stabilité-quantita '!I26) | J22: =IF(D22="","",(STDEV(D22:I22))^2) | K22: =C22 | M22: 4 | N22: 0.968 | O22: 0.906 | P22: 0.864 | Q22: 0.768 | R22: 0.781 | S22: 0.684 | T22: 0.721 | U22: 0.629 | V22: 0.676 | W22: 0.59
B23: =IF('Homogénéité-stabilité-quantita '!D27="","",'Homogénéité-stabilité-quantita '!B27) | C23: =IF('Homogénéité-stabilité-quantita '!D27="","",'Homogénéité-stabilité-quantita '!C27) | D23: =IF('Homogénéité-stabilité-quantita '!D27="","",'Homogénéité-stabilité-quantita '!D27) | E23: =IF('Homogénéité-stabilité-quantita '!E27="","",'Homogénéité-stabilité-quantita '!E27) | F23: =IF('Homogénéité-stabilité-quantita '!F27="","",'Homogénéité-stabilité-quantita '!F27) | G23: =IF('Homogénéité-stabilité-quantita '!G27="","",'Homogénéité-stabilité-quantita '!G27) | H23: =IF('Homogénéité-stabilité-quantita '!H27="","",'Homogénéité-stabilité-quantita '!H27) | I23: =IF('Homogénéité-stabilité-quantita '!I27="","",'Homogénéité-stabilité-quantita '!I27) | J23: =IF(D23="","",(STDEV(D23:I23))^2) | K23: =C23 | M23: 5 | N23: 0.928 | O23: 0.841 | P23: 0.788 | Q23: 0.684 | R23: 0.696 | S23: 0.598 | T23: 0.633 | U23: 0.544 | V23: 0.588 | W23: 0.506
B24: =IF('Homogénéité-stabilité-quantita '!D28="","",'Homogénéité-stabilité-quantita '!B28) | C24: =IF('Homogénéité-stabilité-quantita '!D28="","",'Homogénéité-stabilité-quantita '!C28) | D24: =IF('Homogénéité-stabilité-quantita '!D28="","",'Homogénéité-stabilité-quantita '!D28) | E24: =IF('Homogénéité-stabilité-quantita '!E28="","",'Homogénéité-stabilité-quantita '!E28) | F24: =IF('Homogénéité-stabilité-quantita '!F28="","",'Homogénéité-stabilité-quantita '!F28) | G24: =IF('Homogénéité-stabilité-quantita '!G28="","",'Homogénéité-stabilité-quantita '!G28) | H24: =IF('Homogénéité-stabilité-quantita '!H28="","",'Homogénéité-stabilité-quantita '!H28) | I24: =IF('Homogénéité-stabilité-quantita '!I28="","",'Homogénéité-stabilité-quantita '!I28) | J24: =IF(D24="","",(STDEV(D24:I24))^2) | K24: =C24 | M24: 6 | N24: 0.883 | O24: 0.781 | P24: 0.722 | Q24: 0.616 | R24: 0.626 | S24: 0.532 | T24: 0.564 | U24: 0.48 | V24: 0.52 | W24: 0.445
B25: =IF('Homogénéité-stabilité-quantita '!D29="","",'Homogénéité-stabilité-quantita '!B29) | C25: =IF('Homogénéité-stabilité-quantita '!D29="","",'Homogénéité-stabilité-quantita '!C29) | D25: =IF('Homogénéité-stabilité-quantita '!D29="","",'Homogénéité-stabilité-quantita '!D29) | E25: =IF('Homogénéité-stabilité-quantita '!E29="","",'Homogénéité-stabilité-quantita '!E29) | F25: =IF('Homogénéité-stabilité-quantita '!F29="","",'Homogénéité-stabilité-quantita '!F29) | G25: =IF('Homogénéité-stabilité-quantita '!G29="","",'Homogénéité-stabilité-quantita '!G29) | H25: =IF('Homogénéité-stabilité-quantita '!H29="","",'Homogénéité-stabilité-quantita '!H29) | I25: =IF('Homogénéité-stabilité-quantita '!I29="","",'Homogénéité-stabilité-quantita '!I29) | J25: =IF(D25="","",(STDEV(D25:I25))^2) | K25: =C25 | M25: 7 | N25: 0.838 | O25: 0.727 | P25: 0.664 | Q25: 0.561 | R25: 0.568 | S25: 0.48 | T25: 0.508 | U25: 0.431 | V25: 0.466 | W25: 0.397
B26: =IF('Homogénéité-stabilité-quantita '!D30="","",'Homogénéité-stabilité-quantita '!B30) | C26: =IF('Homogénéité-stabilité-quantita '!D30="","",'Homogénéité-stabilité-quantita '!C30) | D26: =IF('Homogénéité-stabilité-quantita '!D30="","",'Homogénéité-stabilité-quantita '!D30) | E26: =IF('Homogénéité-stabilité-quantita '!E30="","",'Homogénéité-stabilité-quantita '!E30) | F26: =IF('Homogénéité-stabilité-quantita '!F30="","",'Homogénéité-stabilité-quantita '!F30) | G26: =IF('Homogénéité-stabilité-quantita '!G30="","",'Homogénéité-stabilité-quantita '!G30) | H26: =IF('Homogénéité-stabilité-quantita '!H30="","",'Homogénéité-stabilité-quantita '!H30) | I26: =IF('Homogénéité-stabilité-quantita '!I30="","",'Homogénéité-stabilité-quantita '!I30) | J26: =IF(D26="","",(STDEV(D26:I26))^2) | K26: =C26 | M26: 8 | N26: 0.794 | O26: 0.68 | P26: 0.615 | Q26: 0.516 | R26: 0.521 | S26: 0.438 | T26: 0.463 | U26: 0.391 | V26: 0.423 | W26: 0.36
B27: =IF('Homogénéité-stabilité-quantita '!D31="","",'Homogénéité-stabilité-quantita '!B31) | C27: =IF('Homogénéité-stabilité-quantita '!D31="","",'Homogénéité-stabilité-quantita '!C31) | D27: =IF('Homogénéité-stabilité-quantita '!D31="","",'Homogénéité-stabilité-quantita '!D31) | E27: =IF('Homogénéité-stabilité-quantita '!E31="","",'Homogénéité-stabilité-quantita '!E31) | F27: =IF('Homogénéité-stabilité-quantita '!F31="","",'Homogénéité-stabilité-quantita '!F31) | G27: =IF('Homogénéité-stabilité-quantita '!G31="","",'Homogénéité-stabilité-quantita '!G31) | H27: =IF('Homogénéité-stabilité-quantita '!H31="","",'Homogénéité-stabilité-quantita '!H31) | I27: =IF('Homogénéité-stabilité-quantita '!I31="","",'Homogénéité-stabilité-quantita '!I31) | J27: =IF(D27="","",(STDEV(D27:I27))^2) | K27: =C27 | M27: 9 | N27: 0.754 | O27: 0.638 | P27: 0.573 | Q27: 0.478 | R27: 0.481 | S27: 0.403 | T27: 0.425 | U27: 0.358 | V27: 0.387 | W27: 0.329
B28: =IF('Homogénéité-stabilité-quantita '!D32="","",'Homogénéité-stabilité-quantita '!B32) | C28: =IF('Homogénéité-stabilité-quantita '!D32="","",'Homogénéité-stabilité-quantita '!C32) | D28: =IF('Homogénéité-stabilité-quantita '!D32="","",'Homogénéité-stabilité-quantita '!D32) | E28: =IF('Homogénéité-stabilité-quantita '!E32="","",'Homogénéité-stabilité-quantita '!E32) | F28: =IF('Homogénéité-stabilité-quantita '!F32="","",'Homogénéité-stabilité-quantita '!F32) | G28: =IF('Homogénéité-stabilité-quantita '!G32="","",'Homogénéité-stabilité-quantita '!G32) | H28: =IF('Homogénéité-stabilité-quantita '!H32="","",'Homogénéité-stabilité-quantita '!H32) | I28: =IF('Homogénéité-stabilité-quantita '!I32="","",'Homogénéité-stabilité-quantita '!I32) | J28: =IF(D28="","",(STDEV(D28:I28))^2) | K28: =C28 | M28: 10 | N28: 0.718 | O28: 0.602 | P28: 0.536 | Q28: 0.445 | R28: 0.447 | S28: 0.373 | T28: 0.393 | U28: 0.331 | V28: 0.357 | W28: 0.303
B29: =IF('Homogénéité-stabilité-quantita '!D33="","",'Homogénéité-stabilité-quantita '!B33) | C29: =IF('Homogénéité-stabilité-quantita '!D33="","",'Homogénéité-stabilité-quantita '!C33) | D29: =IF('Homogénéité-stabilité-quantita '!D33="","",'Homogénéité-stabilité-quantita '!D33) | E29: =IF('Homogénéité-stabilité-quantita '!E33="","",'Homogénéité-stabilité-quantita '!E33) | F29: =IF('Homogénéité-stabilité-quantita '!F33="","",'Homogénéité-stabilité-quantita '!F33) | G29: =IF('Homogénéité-stabilité-quantita '!G33="","",'Homogénéité-stabilité-quantita '!G33) | H29: =IF('Homogénéité-stabilité-quantita '!H33="","",'Homogénéité-stabilité-quantita '!H33) | I29: =IF('Homogénéité-stabilité-quantita '!I33="","",'Homogénéité-stabilité-quantita '!I33) | J29: =IF(D29="","",(STDEV(D29:I29))^2) | K29: =C29 | M29: 11 | N29: 0.684 | O29: 0.57 | P29: 0.504 | Q29: 0.417 | R29: 0.418 | S29: 0.348 | T29: 0.366 | U29: 0.308 | V29: 0.332 | W29: 0.281
B30: =IF('Homogénéité-stabilité-quantita '!D34="","",'Homogénéité-stabilité-quantita '!B34) | C30: =IF('Homogénéité-stabilité-quantita '!D34="","",'Homogénéité-stabilité-quantita '!C34) | D30: =IF('Homogénéité-stabilité-quantita '!D34="","",'Homogénéité-stabilité-quantita '!D34) | E30: =IF('Homogénéité-stabilité-quantita '!E34="","",'Homogénéité-stabilité-quantita '!E34) | F30: =IF('Homogénéité-stabilité-quantita '!F34="","",'Homogénéité-stabilité-quantita '!F34) | G30: =IF('Homogénéité-stabilité-quantita '!G34="","",'Homogénéité-stabilité-quantita '!G34) | H30: =IF('Homogénéité-stabilité-quantita '!H34="","",'Homogénéité-stabilité-quantita '!H34) | I30: =IF('Homogénéité-stabilité-quantita '!I34="","",'Homogénéité-stabilité-quantita '!I34) | J30: =IF(D30="","",(STDEV(D30:I30))^2) | K30: =C30 | M30: 12 | N30: 0.653 | O30: 0.541 | P30: 0.475 | Q30: 0.392 | R30: 0.392 | S30: 0.326 | T30: 0.343 | U30: 0.288 | V30: 0.31 | W30: 0.262
B31: =IF('Homogénéité-stabilité-quantita '!D35="","",'Homogénéité-stabilité-quantita '!B35) | C31: =IF('Homogénéité-stabilité-quantita '!D35="","",'Homogénéité-stabilité-quantita '!C35) | D31: =IF('Homogénéité-stabilité-quantita '!D35="","",'Homogénéité-stabilité-quantita '!D35) | E31: =IF('Homogénéité-stabilité-quantita '!E35="","",'Homogénéité-stabilité-quantita '!E35) | F31: =IF('Homogénéité-stabilité-quantita '!F35="","",'Homogénéité-stabilité-quantita '!F35) | G31: =IF('Homogénéité-stabilité-quantita '!G35="","",'Homogénéité-stabilité-quantita '!G35) | H31: =IF('Homogénéité-stabilité-quantita '!H35="","",'Homogénéité-stabilité-quantita '!H35) | I31: =IF('Homogénéité-stabilité-quantita '!I35="","",'Homogénéité-stabilité-quantita '!I35) | J31: =IF(D31="","",(STDEV(D31:I31))^2) | K31: =C31 | M31: 13 | N31: 0.624 | O31: 0.515 | P31: 0.45 | Q31: 0.371 | R31: 0.369 | S31: 0.307 | T31: 0.322 | U31: 0.271 | V31: 0.291 | W31: 0.243
B32: =IF('Homogénéité-stabilité-quantita '!D36="","",'Homogénéité-stabilité-quantita '!B36) | C32: =IF('Homogénéité-stabilité-quantita '!D36="","",'Homogénéité-stabilité-quantita '!C36) | D32: =IF('Homogénéité-stabilité-quantita '!D36="","",'Homogénéité-stabilité-quantita '!D36) | E32: =IF('Homogénéité-stabilité-quantita '!E36="","",'Homogénéité-stabilité-quantita '!E36) | F32: =IF('Homogénéité-stabilité-quantita '!F36="","",'Homogénéité-stabilité-quantita '!F36) | G32: =IF('Homogénéité-stabilité-quantita '!G36="","",'Homogénéité-stabilité-quantita '!G36) | H32: =IF('Homogénéité-stabilité-quantita '!H36="","",'Homogénéité-stabilité-quantita '!H36) | I32: =IF('Homogénéité-stabilité-quantita '!I36="","",'Homogénéité-stabilité-quantita '!I36) | J32: =IF(D32="","",(STDEV(D32:I32))^2) | K32: =C32 | M32: 14 | N32: 0.599 | O32: 0.492 | P32: 0.427 | Q32: 0.352 | R32: 0.349 | S32: 0.291 | T32: 0.304 | U32: 0.255 | V32: 0.274 | W32: 0.232
... B38: =IF('Homogénéité-stabilité-quantita '!D42="","",'Homogénéité-stabilité-quantita '!B42) | C38: =IF('Homogénéité-stabilité-quantita '!D42="","",'Homogénéité-stabilité-quantita '!C42) | D38: =IF('Homogénéité-stabilité-quantita '!D42="","",'Homogénéité-stabilité-quantita '!D42) | E38: =IF('Homogénéité-stabilité-quantita '!E42="","",'Homogénéité-stabilité-quantita '!E42) | F38: =IF('Homogénéité-stabilité-quantita '!F42="","",'Homogénéité-stabilité-quantita '!F42) | G38: =IF('Homogénéité-stabilité-quantita '!G42="","",'Homogénéité-stabilité-quantita '!G42) | H38: =IF('Homogénéité-stabilité-quantita '!H42="","",'Homogénéité-stabilité-quantita '!H42) | I38: =IF('Homogénéité-stabilité-quantita '!I42="","",'Homogénéité-stabilité-quantita '!I42) | J38: =IF(D38="","",(STDEV(D38:I38))^2) | K38: =C38 | M38: 20 | N38: 0.48 | O38: 0.389 | P38: 0.33 | Q38: 0.27 | R38: 0.265 | S38: 0.22 | T38: 0.229 | U38: 0.192 | V38: 0.205 | W38: 0.174
C41: Test de Cochran
C42: Vérification | E42: 1
C43: Somme Si² | E43: =IF(D19="","",SUM(J19:J38))
C44: Si²max | E44: =IF(D19="","",MAX(J19:J38))
C45: C | E45: =IF(D19="","",E44/E43)
C46: G critique (1%) | E46: =IF(D19="","",IF(F14=2,VLOOKUP(F13,M20:O38,2,FALSE),IF(F14=3,VLOOKUP(F13,M20:Q38,4,FALSE),IF(F14=4,VLOOKUP(F13,M20:S38,6,FALSE),IF(F14=5,VLOOKUP(F13,M20:U38,8,FALSE),IF(F14=6,VLOOKUP(F13,M20:W38,10,FALSE)))))))
C47: G critique (5%) | E47: =IF(D19="","",IF(F14=2,VLOOKUP(F13,M20:O38,3,FALSE),IF(F14=3,VLOOKUP(F13,M20:Q38,5,FALSE),IF(F14=4,VLOOKUP(F13,M20:S38,7,FALSE),IF(F14=5,VLOOKUP(F13,M20:U38,9,FALSE),IF(F14=6,VLOOKUP(F13,M20:W38,11,FALSE)))))))
C48: Décision | E48: =IF(D19="","",IF(E45<=E47,"Si² correcte",IF(AND(E45>E47,E45<=E46),"Si² isolée","Si² abérrante")))
C49: Valeurs maximales Si | E49: =IF(D19="","",MAX(J19:J38))
C50: Echantillon à éliminer | E50: =IF(D19="","",IF(OR(E48="Si² correcte",E48="Si² isolée"),"Pas de valeurs aberrantes détectées",VLOOKUP(E49,J19:K38,2,0)))
B55: Adresse : BP53 Zone Industrielle Technopole Menzel Harb 5036 TUNISIE Tél : +216 70 146 260 Fax : +216 70 146 269 Mail : info@ttesting.org Page 1/1

Sheet Homogénéité-stabilité-qualita
AB1: Mode
E2: Vérification de l'homogeniété et de la stabilité des échantillons soumises à l'essai d'aptitude | U2: Réference : FTE 006 Version : 06 du 10/08/2026 Page 5/6 | AB2: Médiane
AB3: NOT OK
AB4: Les échantillons ne sont pas homogènes; éliminer les résultats indiqués en rouge. Ne pas éliminer plus que 1 résultat
AB5: Les échantillons sont homogènes
C6: ESSAIS QUALITATIFS ORDINALES | AB6: L'écart entre les valeurs min et max est important vérifier ou si possible remplacer par d'autres résultats
AB7: Les échantillons sont stables
AB8: OK
C10: Référence de la campagne :
C11: Référence de l'échantillon testé :
C12: Méthode testée :
C13: Médiane ou mode? | I13: Médiane | K13: =IF(G25="","",IF(I13=AB1,G36,IF(I13=AB2,G37,"Indiquer Médiane ou Mode")))
C14: ± classe de différence par rapport à la valeur assignée :
C16: I) Vérification de l'homogénieté des échantillons selon l'ISO/IEC 17043: 2023 Annexe B.2.4 page 32
C18: Date des essais d'homogéniété:
C19: Nombre d'échantillons ( g ): | G19: =IF(G25="","",COUNT(G25:G34))
C20: Nombre de prise d'essai ( m ): | G20: =IF(G25="","",COUNT(G25:L25))
C22: Code des rapports TTS | E22: Code d'échantillons d'homogénéité | G22: Résultat 1 | H22: Résultat 2 | I22: Résultat 3 | J22: Résultat 4 | K22: Résultat 5 | L22: Résultat 6 | M22: Décision Résultat 1 | N22: Décision Résultat 2 | O22: Décision Résultat 3 | P22: Décision Résultat 4 | Q22: Décision Résultat 5 | R22: Décision Résultat 6 | S22: Valeur maximale | T22: Valeur minimale | U22: lValeur maximale - valeur minimalel
E25: HO 001 | M25: =IF(G25="","",IF(ABS(G25-$K$13)>$I$14,"NOT OK", "OK")) | N25: =IF(H25="","",IF(ABS(H25-$K$13)>$I$14,"NOT OK", "OK")) | O25: =IF(I25="","",IF(ABS(I25-$K$13)>$I$14,"NOT OK", "OK")) | P25: =IF(J25="","",IF(ABS(J25-$K$13)>$I$14,"NOT OK", "OK")) | Q25: =IF(K25="","",IF(ABS(K25-$K$13)>$I$14,"NOT OK", "OK")) | R25: =IF(L25="","",IF(ABS(L25-$K$13)>$I$14,"NOT OK", "OK")) | S25: =IF(G25="","",MAX(G25:L25)) | T25: =IF(G25="","",MIN(G25:L25)) | U25: =IF(G25="","",ABS(S25-T25))
E26: HO 002 | M26: =IF(G26="","",IF(ABS(G26-$K$13)>$I$14,"NOT OK", "OK")) | N26: =IF(H26="","",IF(ABS(H26-$K$13)>$I$14,"NOT OK", "OK")) | O26: =IF(I26="","",IF(ABS(I26-$K$13)>$I$14,"NOT OK", "OK")) | P26: =IF(J26="","",IF(ABS(J26-$K$13)>$I$14,"NOT OK", "OK")) | Q26: =IF(K26="","",IF(ABS(K26-$K$13)>$I$14,"NOT OK", "OK")) | R26: =IF(L26="","",IF(ABS(L26-$K$13)>$I$14,"NOT OK", "OK")) | S26: =IF(G26="","",MAX(G26:L26)) | T26: =IF(G26="","",MIN(G26:L26)) | U26: =IF(G26="","",ABS(S26-T26))
E27: HO 003 | M27: =IF(G27="","",IF(ABS(G27-$K$13)>$I$14,"NOT OK", "OK")) | N27: =IF(H27="","",IF(ABS(H27-$K$13)>$I$14,"NOT OK", "OK")) | O27: =IF(I27="","",IF(ABS(I27-$K$13)>$I$14,"NOT OK", "OK")) | P27: =IF(J27="","",IF(ABS(J27-$K$13)>$I$14,"NOT OK", "OK")) | Q27: =IF(K27="","",IF(ABS(K27-$K$13)>$I$14,"NOT OK", "OK")) | R27: =IF(L27="","",IF(ABS(L27-$K$13)>$I$14,"NOT OK", "OK")) | S27: =IF(G27="","",MAX(G27:L27)) | T27: =IF(G27="","",MIN(G27:L27)) | U27: =IF(G27="","",ABS(S27-T27))
E28: HO 004 | M28: =IF(G28="","",IF(ABS(G28-$K$13)>$I$14,"NOT OK", "OK")) | N28: =IF(H28="","",IF(ABS(H28-$K$13)>$I$14,"NOT OK", "OK")) | O28: =IF(I28="","",IF(ABS(I28-$K$13)>$I$14,"NOT OK", "OK")) | P28: =IF(J28="","",IF(ABS(J28-$K$13)>$I$14,"NOT OK", "OK")) | Q28: =IF(K28="","",IF(ABS(K28-$K$13)>$I$14,"NOT OK", "OK")) | R28: =IF(L28="","",IF(ABS(L28-$K$13)>$I$14,"NOT OK", "OK")) | S28: =IF(G28="","",MAX(G28:L28)) | T28: =IF(G28="","",MIN(G28:L28)) | U28: =IF(G28="","",ABS(S28-T28))
E29: HO 005 | M29: =IF(G29="","",IF(ABS(G29-$K$13)>$I$14,"NOT OK", "OK")) | N29: =IF(H29="","",IF(ABS(H29-$K$13)>$I$14,"NOT OK", "OK")) | O29: =IF(I29="","",IF(ABS(I29-$K$13)>$I$14,"NOT OK", "OK")) | P29: =IF(J29="","",IF(ABS(J29-$K$13)>$I$14,"NOT OK", "OK")) | Q29: =IF(K29="","",IF(ABS(K29-$K$13)>$I$14,"NOT OK", "OK")) | R29: =IF(L29="","",IF(ABS(L29-$K$13)>$I$14,"NOT OK", "OK")) | S29: =IF(G29="","",MAX(G29:L29)) | T29: =IF(G29="","",MIN(G29:L29)) | U29: =IF(G29="","",ABS(S29-T29))
E30: HO 006 | M30: =IF(G30="","",IF(ABS(G30-$K$13)>$I$14,"NOT OK", "OK")) | N30: =IF(H30="","",IF(ABS(H30-$K$13)>$I$14,"NOT OK", "OK")) | O30: =IF(I30="","",IF(ABS(I30-$K$13)>$I$14,"NOT OK", "OK")) | P30: =IF(J30="","",IF(ABS(J30-$K$13)>$I$14,"NOT OK", "OK")) | Q30: =IF(K30="","",IF(ABS(K30-$K$13)>$I$14,"NOT OK", "OK")) | R30: =IF(L30="","",IF(ABS(L30-$K$13)>$I$14,"NOT OK", "OK")) | S30: =IF(G30="","",MAX(G30:L30)) | T30: =IF(G30="","",MIN(G30:L30)) | U30: =IF(G30="","",ABS(S30-T30))
E31: HO 007 | M31: =IF(G31="","",IF(ABS(G31-$K$13)>$I$14,"NOT OK", "OK")) | N31: =IF(H31="","",IF(ABS(H31-$K$13)>$I$14,"NOT OK", "OK")) | O31: =IF(I31="","",IF(ABS(I31-$K$13)>$I$14,"NOT OK", "OK")) | P31: =IF(J31="","",IF(ABS(J31-$K$13)>$I$14,"NOT OK", "OK")) | Q31: =IF(K31="","",IF(ABS(K31-$K$13)>$I$14,"NOT OK", "OK")) | R31: =IF(L31="","",IF(ABS(L31-$K$13)>$I$14,"NOT OK", "OK")) | S31: =IF(G31="","",MAX(G31:L31)) | T31: =IF(G31="","",MIN(G31:L31)) | U31: =IF(G31="","",ABS(S31-T31))
E32: HO 008 | M32: =IF(G32="","",IF(ABS(G32-$K$13)>$I$14,"NOT OK", "OK")) | N32: =IF(H32="","",IF(ABS(H32-$K$13)>$I$14,"NOT OK", "OK")) | O32: =IF(I32="","",IF(ABS(I32-$K$13)>$I$14,"NOT OK", "OK")) | P32: =IF(J32="","",IF(ABS(J32-$K$13)>$I$14,"NOT OK", "OK")) | Q32: =IF(K32="","",IF(ABS(K32-$K$13)>$I$14,"NOT OK", "OK")) | R32: =IF(L32="","",IF(ABS(L32-$K$13)>$I$14,"NOT OK", "OK")) | S32: =IF(G32="","",MAX(G32:L32)) | T32: =IF(G32="","",MIN(G32:L32)) | U32: =IF(G32="","",ABS(S32-T32))
E33: HO 009 | M33: =IF(G33="","",IF(ABS(G33-$K$13)>$I$14,"NOT OK", "OK")) | N33: =IF(H33="","",IF(ABS(H33-$K$13)>$I$14,"NOT OK", "OK")) | O33: =IF(I33="","",IF(ABS(I33-$K$13)>$I$14,"NOT OK", "OK")) | P33: =IF(J33="","",IF(ABS(J33-$K$13)>$I$14,"NOT OK", "OK")) | Q33: =IF(K33="","",IF(ABS(K33-$K$13)>$I$14,"NOT OK", "OK")) | R33: =IF(L33="","",IF(ABS(L33-$K$13)>$I$14,"NOT OK", "OK")) | S33: =IF(G33="","",MAX(G33:L33)) | T33: =IF(G33="","",MIN(G33:L33)) | U33: =IF(G33="","",ABS(S33-T33))
E34: HO 010 | M34: =IF(G34="","",IF(ABS(G34-$K$13)>$I$14,"NOT OK", "OK")) | N34: =IF(H34="","",IF(ABS(H34-$K$13)>$I$14,"NOT OK", "OK")) | O34: =IF(I34="","",IF(ABS(I34-$K$13)>$I$14,"NOT OK", "OK")) | P34: =IF(J34="","",IF(ABS(J34-$K$13)>$I$14,"NOT OK", "OK")) | Q34: =IF(K34="","",IF(ABS(K34-$K$13)>$I$14,"NOT OK", "OK")) | R34: =IF(L34="","",IF(ABS(L34-$K$13)>$I$14,"NOT OK", "OK")) | S34: =IF(G34="","",MAX(G34:L34)) | T34: =IF(G34="","",MIN(G34:L34)) | U34: =IF(G34="","",ABS(S34-T34))
C36: Mode: | G36: =IF(C25="","",_xlfn.MODE.SNGL(G25:L34))
C37: Médiane: | G37: =IF(C25="","",MEDIAN(G25:L34))
C38: Décision sur l'homogénéité de l'entité souumise à l'Ed'A: | G38: =IF(G25="","", IF(AND(OR(M25=$AB$8,M25=""),OR(M26=$AB$8,M26=""),OR(M27=$AB$8,M27=""),OR(M28=$AB$8,M28=""),OR(M29=$AB$8,M29=""),OR(M30=$AB$8,M30=""),OR(M31=$AB$8,M31=""),OR(M32=$AB$8,M32=""),OR(M33=$AB$8,M33=""),OR(M34=$AB$8,M34=""),OR(N25=$AB$8,N25=""),OR(N26=$AB$8,N26=""),OR(N27=$AB$8,N27=""),OR(N28=$AB$8,N28=""),OR(N29=$AB$8,N29=""),OR(N30=$AB$8,N30=""),OR(N31=$AB$8,N31=""),OR(N32=$AB$8,N32=""),OR(N33=$AB$8,N33=""),OR(N34=$AB$8,N34=""),OR(O25=$AB$8,O25=""),OR(O26=$AB$8,O26=""),OR(O27=$AB$8,O27=""),OR(O28=$AB$8,O28=""),OR(O29=$AB$8,O29=""),OR(O30=$AB$8,O30=""),OR(O31=$AB$8,O31=""),OR(O32=$AB$8,O32=""),OR(O33=$AB$8,O33=""),OR(O34=$AB$8,O34=""),OR(P25=$AB$8,P25=""),OR(P26=$AB$8,P26=""),OR(P27=$AB$8,P27=""),OR(P28=$AB$8,P28=""),OR(P29=$AB$8,P29=""),OR(P30=$AB$8,P30=""),OR(P31=$AB$8,P31=""),OR(P32=$AB$8,P32=""),OR(P33=$AB$8,P33=""),OR(P34=$AB$8,P34=""),OR(Q25=$AB$8,Q25=""),OR(Q26=$AB$8,Q26=""),OR(Q27=$AB$8,Q27=""),OR(Q28=$AB$8,Q28=""),OR(Q29=$AB$8,Q29=""),OR(Q30=$AB$8,Q30=""),OR(Q31=$AB$8,Q31=""),OR(Q32=$AB$8,Q32=""),OR(Q33=$AB$8,Q33=""),OR(Q34=$AB$8,Q34=""),OR(R25=$AB$8,R25=""),OR(R26=$AB$8,R26=""),OR(R27=$AB$8,R27=""),OR(R28=$AB$8,R28=""),OR(R29=$AB$8,R29=""),OR(R30=$AB$8,R30=""),OR(R31=$AB$8,R31=""),OR(R32=$AB$8,R32=""),OR(R33=$AB$8,R33=""),OR(R34=$AB$8, R34=""),OR(U25<=$I$14,U25=""),OR(U26<=$I$14,U26=""),OR(U27<=$I$14,U27=""),OR(U28<=$I$14,U28=""),OR(U29<=$I$14,U29=""),OR(U30<=$I$14,U30=""),OR(U31<=$I$14,U31=""),OR(U32<=$I$14,U32=""),OR(U33<=$I$14,U33=""),OR(U34<=$I$14,U34="")),"Les échantillons sont homogènes", "Les échantillons ne sont pas homogènes; éliminer les résultats indiqués en rouge. Ne pas éliminer plus que 1 résultat"))
C44: Résultat éliminé s'il y'a lieu :
C46: II) Vérification de la stabilité des échantillons à la fin de la période du déroulement de l'essai d'aptitude selon l'ISO/IEC 17043: 2023 Annexe B.2.4 page 32
C48: II.1) Vérification de la stabilité à la fin de l'essai d'aptitude
C50: Date de fin de l'essai d'aptitude
C51: Date des essais de stabilité
C52: Choisir nombre d'échantillons ( g ) | G52: =IF(G62="","",COUNT(G62:G65))
C53: Nombre de prise d'essai ( m ) | G53: =IF(G62="","",COUNT(G62:L62))
C55: Résultats avant distribution des entités soumises à l'Ed'A = Résultats homogénéité
C56: Mode : | H56: =IF(C25="","",G36)
...

Sheet Homogénéité-stabilité-solidité
AA1: Mode
E2: Vérification de l'homogeniété et de la stabilité des échantillons soumises à l'essai d'aptitude | V2: Réference : FTE 006 Version : 06 du 10/08/2026 Page 6/6 | AA2: Médiane
AA3: NOT OK
AA4: OK
D6: ESSAIS QUALITATIFS ORDINALES (Essais de solidité)
B9: Référence de la campagne :
B10: Référence de l'échantillon testé :
B11: Méthode testée :
B12: Médiane ou mode? | H12: Mode | I12: Dégradation de couleur | J12: Dégorgement - Acétate (CA) | K12: Dégorgement - Cotton (CO) | L12: Dégorgement - Polyamide (PA) | M12: Dégorgement - Polyester(PES) | N12: Dégorgement - Polyacrylique (PAN) | O12: Dégorgement - Laine (WO) | P12: Dégorgement - Triacétate (CTA) | Q12: Dégorgement - Viscose (CV)
I13: =IF(F25="","",IF($H$12=$AA$1,F69,IF($H$12=$AA$2,F70,"Indiquer Médiane ou Mode"))) | J13: =IF(G25="","",IF($H$12=$AA$1,G69,IF($H$12=$AA$2,G70,"Indiquer Médiane ou Mode"))) | K13: =IF(H25="","",IF($H$12=$AA$1,H69,IF($H$12=$AA$2,H70,"Indiquer Médiane ou Mode"))) | L13: =IF(I25="","",IF($H$12=$AA$1,I69,IF($H$12=$AA$2,I70,"Indiquer Médiane ou Mode"))) | M13: =IF(J25="","",IF($H$12=$AA$1,J69,IF($H$12=$AA$2,J70,"Indiquer Médiane ou Mode"))) | N13: =IF(K25="","",IF($H$12=$AA$1,K69,IF($H$12=$AA$2,K70,"Indiquer Médiane ou Mode"))) | O13: =IF(L25="","",IF($H$12=$AA$1,L69,IF($H$12=$AA$2,L70,"Indiquer Médiane ou Mode"))) | P13: =IF(M25="","",IF($H$12=$AA$1,M69,IF($H$12=$AA$2,M70,"Indiquer Médiane ou Mode"))) | Q13: =IF(N25="","",IF($H$12=$AA$1,N69,IF($H$12=$AA$2,N70,"Indiquer Médiane ou Mode")))
B14: ± classe de différence par rapporrt à la valeur assignée :
B16: I) Vérification de l'homogénieté des échantillons selon l'ISO/IEC 17043: 2023 Annexe B.2.4 page 32
B18: Date des essais d'homogéniété:
B19: Nombre d'échantillons ( g ): | E19: =IF(F25="","",COUNT(F25:F34))
B20: Nombre de prise d'essai ( m ): | E20: 2
B22: Code des rapports TTS | D22: Code d'échantillons d'homogénéité | F22: Résultat 1 | O22: Décision Résultat 1
F23: Dégradation de couleur | G23: Dégorgement - Acétate (CA) | H23: Dégorgement - Cotton (CO) | I23: Dégorgement - Polyamide (PA) | J23: Dégorgement - Polyester(PES) | K23: Dégorgement - Polyacrylique (PAN) | L23: Dégorgement - Laine (WO) | M23: Dégorgement - Triacétate (CTA) | N23: Dégorgement - Viscose (CV) | O23: Dégradation de couleur | P23: Dégorgement - Acétate (CA) | Q23: Dégorgement - Cotton (CO) | R23: Dégorgement - Polyamide (PA) | S23: Dégorgement - Polyester(PES) | T23: Dégorgement - Polyacrylique (PAN) | U23: Dégorgement - Laine (WO) | V23: Dégorgement - Triacétate (CTA) | W23: Dégorgement - Viscose (CV)
D25: HO 001 | O25: =IF(F25="","",IF(ABS(F25-$I$13)>$H$14,"NOT OK", "OK")) | P25: =IF(G25="","",IF(ABS(G25-$J$13)>$H$14,"NOT OK", "OK")) | Q25: =IF(H25="","",IF(ABS(H25-$K$13)>$H$14,"NOT OK", "OK")) | R25: =IF(I25="","",IF(ABS(I25-$L$13)>$H$14,"NOT OK", "OK")) | S25: =IF(J25="","",IF(ABS(J25-$M$13)>$H$14,"NOT OK", "OK")) | T25: =IF(K25="","",IF(ABS(K25-$N$13)>$H$14,"NOT OK", "OK")) | U25: =IF(L25="","",IF(ABS(L25-$O$13)>$H$14,"NOT OK", "OK")) | V25: =IF(M25="","",IF(ABS(M25-$P$13)>$H$14,"NOT OK", "OK")) | W25: =IF(N25="","",IF(ABS(N25-$Q$13)>$H$14,"NOT OK", "OK"))
D26: HO 002 | O26: =IF(F26="","",IF(ABS(F26-$I$13)>$H$14,"NOT OK", "OK")) | P26: =IF(G26="","",IF(ABS(G26-$J$13)>$H$14,"NOT OK", "OK")) | Q26: =IF(H26="","",IF(ABS(H26-$K$13)>$H$14,"NOT OK", "OK")) | R26: =IF(I26="","",IF(ABS(I26-$L$13)>$H$14,"NOT OK", "OK")) | S26: =IF(J26="","",IF(ABS(J26-$M$13)>$H$14,"NOT OK", "OK")) | T26: =IF(K26="","",IF(ABS(K26-$N$13)>$H$14,"NOT OK", "OK")) | U26: =IF(L26="","",IF(ABS(L26-$O$13)>$H$14,"NOT OK", "OK")) | V26: =IF(M26="","",IF(ABS(M26-$P$13)>$H$14,"NOT OK", "OK")) | W26: =IF(N26="","",IF(ABS(N26-$Q$13)>$H$14,"NOT OK", "OK"))
D27: HO 003 | O27: =IF(F27="","",IF(ABS(F27-$I$13)>$H$14,"NOT OK", "OK")) | P27: =IF(G27="","",IF(ABS(G27-$J$13)>$H$14,"NOT OK", "OK")) | Q27: =IF(H27="","",IF(ABS(H27-$K$13)>$H$14,"NOT OK", "OK")) | R27: =IF(I27="","",IF(ABS(I27-$L$13)>$H$14,"NOT OK", "OK")) | S27: =IF(J27="","",IF(ABS(J27-$M$13)>$H$14,"NOT OK", "OK")) | T27: =IF(K27="","",IF(ABS(K27-$N$13)>$H$14,"NOT OK", "OK")) | U27: =IF(L27="","",IF(ABS(L27-$O$13)>$H$14,"NOT OK", "OK")) | V27: =IF(M27="","",IF(ABS(M27-$P$13)>$H$14,"NOT OK", "OK")) | W27: =IF(N27="","",IF(ABS(N27-$Q$13)>$H$14,"NOT OK", "OK"))
D28: HO 004 | O28: =IF(F28="","",IF(ABS(F28-$I$13)>$H$14,"NOT OK", "OK")) | P28: =IF(G28="","",IF(ABS(G28-$J$13)>$H$14,"NOT OK", "OK")) | Q28: =IF(H28="","",IF(ABS(H28-$K$13)>$H$14,"NOT OK", "OK")) | R28: =IF(I28="","",IF(ABS(I28-$L$13)>$H$14,"NOT OK", "OK")) | S28: =IF(J28="","",IF(ABS(J28-$M$13)>$H$14,"NOT OK", "OK")) | T28: =IF(K28="","",IF(ABS(K28-$N$13)>$H$14,"NOT OK", "OK")) | U28: =IF(L28="","",IF(ABS(L28-$O$13)>$H$14,"NOT OK", "OK")) | V28: =IF(M28="","",IF(ABS(M28-$P$13)>$H$14,"NOT OK", "OK")) | W28: =IF(N28="","",IF(ABS(N28-$Q$13)>$H$14,"NOT OK", "OK"))
D29: HO 005 | O29: =IF(F29="","",IF(ABS(F29-$I$13)>$H$14,"NOT OK", "OK")) | P29: =IF(G29="","",IF(ABS(G29-$J$13)>$H$14,"NOT OK", "OK")) | Q29: =IF(H29="","",IF(ABS(H29-$K$13)>$H$14,"NOT OK", "OK")) | R29: =IF(I29="","",IF(ABS(I29-$L$13)>$H$14,"NOT OK", "OK")) | S29: =IF(J29="","",IF(ABS(J29-$M$13)>$H$14,"NOT OK", "OK")) | T29: =IF(K29="","",IF(ABS(K29-$N$13)>$H$14,"NOT OK", "OK")) | U29: =IF(L29="","",IF(ABS(L29-$O$13)>$H$14,"NOT OK", "OK")) | V29: =IF(M29="","",IF(ABS(M29-$P$13)>$H$14,"NOT OK", "OK")) | W29: =IF(N29="","",IF(ABS(N29-$Q$13)>$H$14,"NOT OK", "OK"))
D30: HO 006 | O30: =IF(F30="","",IF(ABS(F30-$I$13)>$H$14,"NOT OK", "OK")) | P30: =IF(G30="","",IF(ABS(G30-$J$13)>$H$14,"NOT OK", "OK")) | Q30: =IF(H30="","",IF(ABS(H30-$K$13)>$H$14,"NOT OK", "OK")) | R30: =IF(I30="","",IF(ABS(I30-$L$13)>$H$14,"NOT OK", "OK")) | S30: =IF(J30="","",IF(ABS(J30-$M$13)>$H$14,"NOT OK", "OK")) | T30: =IF(K30="","",IF(ABS(K30-$N$13)>$H$14,"NOT OK", "OK")) | U30: =IF(L30="","",IF(ABS(L30-$O$13)>$H$14,"NOT OK", "OK")) | V30: =IF(M30="","",IF(ABS(M30-$P$13)>$H$14,"NOT OK", "OK")) | W30: =IF(N30="","",IF(ABS(N30-$Q$13)>$H$14,"NOT OK", "OK"))
D31: HO 007 | O31: =IF(F31="","",IF(ABS(F31-$I$13)>$H$14,"NOT OK", "OK")) | P31: =IF(G31="","",IF(ABS(G31-$J$13)>$H$14,"NOT OK", "OK")) | Q31: =IF(H31="","",IF(ABS(H31-$K$13)>$H$14,"NOT OK", "OK")) | R31: =IF(I31="","",IF(ABS(I31-$L$13)>$H$14,"NOT OK", "OK")) | S31: =IF(J31="","",IF(ABS(J31-$M$13)>$H$14,"NOT OK", "OK")) | T31: =IF(K31="","",IF(ABS(K31-$N$13)>$H$14,"NOT OK", "OK")) | U31: =IF(L31="","",IF(ABS(L31-$O$13)>$H$14,"NOT OK", "OK")) | V31: =IF(M31="","",IF(ABS(M31-$P$13)>$H$14,"NOT OK", "OK")) | W31: =IF(N31="","",IF(ABS(N31-$Q$13)>$H$14,"NOT OK", "OK"))
D32: HO 008 | O32: =IF(F32="","",IF(ABS(F32-$I$13)>$H$14,"NOT OK", "OK")) | P32: =IF(G32="","",IF(ABS(G32-$J$13)>$H$14,"NOT OK", "OK")) | Q32: =IF(H32="","",IF(ABS(H32-$K$13)>$H$14,"NOT OK", "OK")) | R32: =IF(I32="","",IF(ABS(I32-$L$13)>$H$14,"NOT OK", "OK")) | S32: =IF(J32="","",IF(ABS(J32-$M$13)>$H$14,"NOT OK", "OK")) | T32: =IF(K32="","",IF(ABS(K32-$N$13)>$H$14,"NOT OK", "OK")) | U32: =IF(L32="","",IF(ABS(L32-$O$13)>$H$14,"NOT OK", "OK")) | V32: =IF(M32="","",IF(ABS(M32-$P$13)>$H$14,"NOT OK", "OK")) | W32: =IF(N32="","",IF(ABS(N32-$Q$13)>$H$14,"NOT OK", "OK"))
D33: HO 009 | O33: =IF(F33="","",IF(ABS(F33-$I$13)>$H$14,"NOT OK", "OK")) | P33: =IF(G33="","",IF(ABS(G33-$J$13)>$H$14,"NOT OK", "OK")) | Q33: =IF(H33="","",IF(ABS(H33-$K$13)>$H$14,"NOT OK", "OK")) | R33: =IF(I33="","",IF(ABS(I33-$L$13)>$H$14,"NOT OK", "OK")) | S33: =IF(J33="","",IF(ABS(J33-$M$13)>$H$14,"NOT OK", "OK")) | T33: =IF(K33="","",IF(ABS(K33-$N$13)>$H$14,"NOT OK", "OK")) | U33: =IF(L33="","",IF(ABS(L33-$O$13)>$H$14,"NOT OK", "OK")) | V33: =IF(M33="","",IF(ABS(M33-$P$13)>$H$14,"NOT OK", "OK")) | W33: =IF(N33="","",IF(ABS(N33-$Q$13)>$H$14,"NOT OK", "OK"))
D34: HO 010 | O34: =IF(F34="","",IF(ABS(F34-$I$13)>$H$14,"NOT OK", "OK")) | P34: =IF(G34="","",IF(ABS(G34-$J$13)>$H$14,"NOT OK", "OK")) | Q34: =IF(H34="","",IF(ABS(H34-$K$13)>$H$14,"NOT OK", "OK")) | R34: =IF(I34="","",IF(ABS(I34-$L$13)>$H$14,"NOT OK", "OK")) | S34: =IF(J34="","",IF(ABS(J34-$M$13)>$H$14,"NOT OK", "OK")) | T34: =IF(K34="","",IF(ABS(K34-$N$13)>$H$14,"NOT OK", "OK")) | U34: =IF(L34="","",IF(ABS(L34-$O$13)>$H$14,"NOT OK", "OK")) | V34: =IF(M34="","",IF(ABS(M34-$P$13)>$H$14,"NOT OK", "OK")) | W34: =IF(N34="","",IF(ABS(N34-$Q$13)>$H$14,"NOT OK", "OK"))
B37: Code des rapports TTS | D37: Code d'échantillons d'homogénéité | F37: Résultat 2 | O37: Décision Résultat 2
F38: Dégradation de couleur | G38: Dégorgement - Acétate (CA) | H38: Dégorgement - Cotton (CO) | I38: Dégorgement - Polyamide (PA) | J38: Dégorgement - Polyester(PES) | K38: Dégorgement - Polyacrylique (PAN) | L38: Dégorgement - Laine (WO) | M38: Dégorgement - Triacétate (CTA) | N38: Dégorgement - Viscose (CV) | O38: Dégradation de couleur | P38: Dégorgement - Acétate (CA) | Q38: Dégorgement - Cotton (CO) | R38: Dégorgement - Polyamide (PA) | S38: Dégorgement - Polyester(PES) | T38: Dégorgement - Polyacrylique (PAN) | U38: Dégorgement - Laine (WO) | V38: Dégorgement - Triacétate (CTA) | W38: Dégorgement - Viscose (CV)
D40: HO 001 | O40: =IF(F40="","",IF(ABS(F40-$I$13)>$H$14,"NOT OK", "OK")) | P40: =IF(G40="","",IF(ABS(G40-$J$13)>$H$14,"NOT OK", "OK")) | Q40: =IF(H40="","",IF(ABS(H40-$K$13)>$H$14,"NOT OK", "OK")) | R40: =IF(I40="","",IF(ABS(I40-$L$13)>$H$14,"NOT OK", "OK")) | S40: =IF(J40="","",IF(ABS(J40-$M$13)>$H$14,"NOT OK", "OK")) | T40: =IF(K40="","",IF(ABS(K40-$N$13)>$H$14,"NOT OK", "OK")) | U40: =IF(L40="","",IF(ABS(L40-$O$13)>$H$14,"NOT OK", "OK")) | V40: =IF(M40="","",IF(ABS(M40-$P$13)>$H$14,"NOT OK", "OK")) | W40: =IF(N40="","",IF(ABS(N40-$Q$13)>$H$14,"NOT OK", "OK"))
D41: HO 002 | O41: =IF(F41="","",IF(ABS(F41-$I$13)>$H$14,"NOT OK", "OK")) | P41: =IF(G41="","",IF(ABS(G41-$J$13)>$H$14,"NOT OK", "OK")) | Q41: =IF(H41="","",IF(ABS(H41-$K$13)>$H$14,"NOT OK", "OK")) | R41: =IF(I41="","",IF(ABS(I41-$L$13)>$H$14,"NOT OK", "OK")) | S41: =IF(J41="","",IF(ABS(J41-$M$13)>$H$14,"NOT OK", "OK")) | T41: =IF(K41="","",IF(ABS(K41-$N$13)>$H$14,"NOT OK", "OK")) | U41: =IF(L41="","",IF(ABS(L41-$O$13)>$H$14,"NOT OK", "OK")) | V41: =IF(M41="","",IF(ABS(M41-$P$13)>$H$14,"NOT OK", "OK")) | W41: =IF(N41="","",IF(ABS(N41-$Q$13)>$H$14,"NOT OK", "OK"))
D42: HO 003 | O42: =IF(F42="","",IF(ABS(F42-$I$13)>$H$14,"NOT OK", "OK")) | P42: =IF(G42="","",IF(ABS(G42-$J$13)>$H$14,"NOT OK", "OK")) | Q42: =IF(H42="","",IF(ABS(H42-$K$13)>$H$14,"NOT OK", "OK")) | R42: =IF(I42="","",IF(ABS(I42-$L$13)>$H$14,"NOT OK", "OK")) | S42: =IF(J42="","",IF(ABS(J42-$M$13)>$H$14,"NOT OK", "OK")) | T42: =IF(K42="","",IF(ABS(K42-$N$13)>$H$14,"NOT OK", "OK")) | U42: =IF(L42="","",IF(ABS(L42-$O$13)>$H$14,"NOT OK", "OK")) | V42: =IF(M42="","",IF(ABS(M42-$P$13)>$H$14,"NOT OK", "OK")) | W42: =IF(N42="","",IF(ABS(N42-$Q$13)>$H$14,"NOT OK", "OK"))
D43: HO 004 | O43: =IF(F43="","",IF(ABS(F43-$I$13)>$H$14,"NOT OK", "OK")) | P43: =IF(G43="","",IF(ABS(G43-$J$13)>$H$14,"NOT OK", "OK")) | Q43: =IF(H43="","",IF(ABS(H43-$K$13)>$H$14,"NOT OK", "OK")) | R43: =IF(I43="","",IF(ABS(I43-$L$13)>$H$14,"NOT OK", "OK")) | S43: =IF(J43="","",IF(ABS(J43-$M$13)>$H$14,"NOT OK", "OK")) | T43: =IF(K43="","",IF(ABS(K43-$N$13)>$H$14,"NOT OK", "OK")) | U43: =IF(L43="","",IF(ABS(L43-$O$13)>$H$14,"NOT OK", "OK")) | V43: =IF(M43="","",IF(ABS(M43-$P$13)>$H$14,"NOT OK", "OK")) | W43: =IF(N43="","",IF(ABS(N43-$Q$13)>$H$14,"NOT OK", "OK"))
D44: HO 005 | O44: =IF(F44="","",IF(ABS(F44-$I$13)>$H$14,"NOT OK", "OK")) | P44: =IF(G44="","",IF(ABS(G44-$J$13)>$H$14,"NOT OK", "OK")) | Q44: =IF(H44="","",IF(ABS(H44-$K$13)>$H$14,"NOT OK", "OK")) | R44: =IF(I44="","",IF(ABS(I44-$L$13)>$H$14,"NOT OK", "OK")) | S44: =IF(J44="","",IF(ABS(J44-$M$13)>$H$14,"NOT OK", "OK")) | T44: =IF(K44="","",IF(ABS(K44-$N$13)>$H$14,"NOT OK", "OK")) | U44: =IF(L44="","",IF(ABS(L44-$O$13)>$H$14,"NOT OK", "OK")) | V44: =IF(M44="","",IF(ABS(M44-$P$13)>$H$14,"NOT OK", "OK")) | W44: =IF(N44="","",IF(ABS(N44-$Q$13)>$H$14,"NOT OK", "OK"))
D45: HO 006 | O45: =IF(F45="","",IF(ABS(F45-$I$13)>$H$14,"NOT OK", "OK")) | P45: =IF(G45="","",IF(ABS(G45-$J$13)>$H$14,"NOT OK", "OK")) | Q45: =IF(H45="","",IF(ABS(H45-$K$13)>$H$14,"NOT OK", "OK")) | R45: =IF(I45="","",IF(ABS(I45-$L$13)>$H$14,"NOT OK", "OK")) | S45: =IF(J45="","",IF(ABS(J45-$M$13)>$H$14,"NOT OK", "OK")) | T45: =IF(K45="","",IF(ABS(K45-$N$13)>$H$14,"NOT OK", "OK")) | U45: =IF(L45="","",IF(ABS(L45-$O$13)>$H$14,"NOT OK", "OK")) | V45: =IF(M45="","",IF(ABS(M45-$P$13)>$H$14,"NOT OK", "OK")) | W45: =IF(N45="","",IF(ABS(N45-$Q$13)>$H$14,"NOT OK", "OK"))
D46: HO 007 | O46: =IF(F46="","",IF(ABS(F46-$I$13)>$H$14,"NOT OK", "OK")) | P46: =IF(G46="","",IF(ABS(G46-$J$13)>$H$14,"NOT OK", "OK")) | Q46: =IF(H46="","",IF(ABS(H46-$K$13)>$H$14,"NOT OK", "OK")) | R46: =IF(I46="","",IF(ABS(I46-$L$13)>$H$14,"NOT OK", "OK")) | S46: =IF(J46="","",IF(ABS(J46-$M$13)>$H$14,"NOT OK", "OK")) | T46: =IF(K46="","",IF(ABS(K46-$N$13)>$H$14,"NOT OK", "OK")) | U46: =IF(L46="","",IF(ABS(L46-$O$13)>$H$14,"NOT OK", "OK")) | V46: =IF(M46="","",IF(ABS(M46-$P$13)>$H$14,"NOT OK", "OK")) | W46: =IF(N46="","",IF(ABS(N46-$Q$13)>$H$14,"NOT OK", "OK"))
D47: HO 008 | O47: =IF(F47="","",IF(ABS(F47-$I$13)>$H$14,"NOT OK", "OK")) | P47: =IF(G47="","",IF(ABS(G47-$J$13)>$H$14,"NOT OK", "OK")) | Q47: =IF(H47="","",IF(ABS(H47-$K$13)>$H$14,"NOT OK", "OK")) | R47: =IF(I47="","",IF(ABS(I47-$L$13)>$H$14,"NOT OK", "OK")) | S47: =IF(J47="","",IF(ABS(J47-$M$13)>$H$14,"NOT OK", "OK")) | T47: =IF(K47="","",IF(ABS(K47-$N$13)>$H$14,"NOT OK", "OK")) | U47: =IF(L47="","",IF(ABS(L47-$O$13)>$H$14,"NOT OK", "OK")) | V47: =IF(M47="","",IF(ABS(M47-$P$13)>$H$14,"NOT OK", "OK")) | W47: =IF(N47="","",IF(ABS(N47-$Q$13)>$H$14,"NOT OK", "OK"))
D48: HO 009 | O48: =IF(F48="","",IF(ABS(F48-$I$13)>$H$14,"NOT OK", "OK")) | P48: =IF(G48="","",IF(ABS(G48-$J$13)>$H$14,"NOT OK", "OK")) | Q48: =IF(H48="","",IF(ABS(H48-$K$13)>$H$14,"NOT OK", "OK")) | R48: =IF(I48="","",IF(ABS(I48-$L$13)>$H$14,"NOT OK", "OK")) | S48: =IF(J48="","",IF(ABS(J48-$M$13)>$H$14,"NOT OK", "OK")) | T48: =IF(K48="","",IF(ABS(K48-$N$13)>$H$14,"NOT OK", "OK")) | U48: =IF(L48="","",IF(ABS(L48-$O$13)>$H$14,"NOT OK", "OK")) | V48: =IF(M48="","",IF(ABS(M48-$P$13)>$H$14,"NOT OK", "OK")) | W48: =IF(N48="","",IF(ABS(N48-$Q$13)>$H$14,"NOT OK", "OK"))
D49: HO 010 | O49: =IF(F49="","",IF(ABS(F49-$I$13)>$H$14,"NOT OK", "OK")) | P49: =IF(G49="","",IF(ABS(G49-$J$13)>$H$14,"NOT OK", "OK")) | Q49: =IF(H49="","",IF(ABS(H49-$K$13)>$H$14,"NOT OK", "OK")) | R49: =IF(I49="","",IF(ABS(I49-$L$13)>$H$14,"NOT OK", "OK")) | S49: =IF(J49="","",IF(ABS(J49-$M$13)>$H$14,"NOT OK", "OK")) | T49: =IF(K49="","",IF(ABS(K49-$N$13)>$H$14,"NOT OK", "OK")) | U49: =IF(L49="","",IF(ABS(L49-$O$13)>$H$14,"NOT OK", "OK")) | V49: =IF(M49="","",IF(ABS(M49-$P$13)>$H$14,"NOT OK", "OK")) | W49: =IF(N49="","",IF(ABS(N49-$Q$13)>$H$14,"NOT OK", "OK"))
F52: lx1-x2l
...
